Workbook

Sheet 1. Cover & Instructions
B3: Aramco Taleed & Roland Berger
B4: Procurement Performance Self-Assessment Framework
B5: A diagnostic tool for procurement maturity and performance
B8: Purpose
B9: This self-assessment framework enables procurement leaders to benchmark the maturity of their function across four critical capability areas — Category Management, Spend Analysis, Strategic Sourcing, and Supplier Relationship Management. It is designed as a structured diagnostic to surface strengths, identify capability gaps, and prioritize improvement initiatives. Results are intended to inform internal dialogue and strategic planning, not to score individuals.
B11: How to complete the assessment
B12: Step 1 | C12: Open the '2. Self-Assessment' sheet.
B13: Step 2 | C13: For each question, select 'Yes' or 'No' from the drop-down in the Response column.
B14: Step 3 | C14: Answer all 40 questions. 'Yes' indicates the practice is consistently in place; 'No' indicates a gap or partial implementation.
B15: Step 4 | C15: When fully completed, open the '3. Results Dashboard' to view your scores, maturity grade, and priority areas.
B16: Step 5 | C16: Refer to the '4. Recommendations' sheet for tailored improvement actions by dimension.
B18: Scoring methodology
B19: Response scale | C19: Each 'Yes' answer is worth 1 point; each 'No' answer is worth 0 points.
B20: Dimension score | C20: Yes answers within a dimension divided by total questions in that dimension, expressed as a percentage.
B21: Overall score | C21: Total Yes answers divided by total questions (40), expressed as a percentage from 0% to 100%.
B22: Interpretation | C22: Higher scores indicate stronger procurement maturity; lower scores indicate priority areas for improvement.
B24: Maturity score bands
B25: Score band | C25: Maturity level and interpretation
B26: 0% – 40% | C26: Foundational — Significant room for improvement; build core procurement capabilities.
B27: 41% – 65% | C27: Developing — Capabilities are in place in parts of the function but not yet consistent.
B28: 66% – 80% | C28: Advanced — Good procurement performance with selective opportunities for further uplift.
B29: 81% – 100% | C29: Best-in-Class — Procurement is a strategic value driver; focus on sustaining excellence.

Sheet 2. Self-Assessment
B3: Self-Assessment Questionnaire
B4: Answer each question with Yes or No. 'Yes' indicates the practice is consistently in place across the function.
B6: # | C6: Question | D6: Response | E6: Points
B7: 1. CATEGORY MANAGEMENT
B8: 1.1 | C8: Do you have formally documented category strategies for your top 3–5 spend categories, reviewed and updated at least annually? | E8: =IF(D8="Yes",1,IF(D8="No",0,""))
B9: 1.2 | C9: Are your category strategies developed cross-functionally, involving stakeholders from operations, finance, and business units — not solely by procurement? | E9: =IF(D9="Yes",1,IF(D9="No",0,""))
B10: 1.3 | C10: Have you segmented your entire spend portfolio into a structured category hierarchy with a minimum of 3 levels (category → sub-category → commodity)? | E10: =IF(D10="Yes",1,IF(D10="No",0,""))
B11: 1.4 | C11: Does each major spend category have a formally designated category owner, accountable for strategy execution and performance tracking? | E11: =IF(D11="Yes",1,IF(D11="No",0,""))
B12: 1.5 | C12: Do your category strategies explicitly define the preferred buying channel for each category (e.g., framework agreements, catalogue purchasing, spot buy)? | E12: =IF(D12="Yes",1,IF(D12="No",0,""))
B13: 1.6 | C13: Are category strategies updated whenever there is a significant change in supply market conditions, pricing dynamics, or internal demand patterns? | E13: =IF(D13="Yes",1,IF(D13="No",0,""))
B14: 1.7 | C14: Do you conduct formal category performance reviews at least quarterly, measuring against defined KPIs such as savings delivered, contract compliance, and supplier performance? | E14: =IF(D14="Yes",1,IF(D14="No",0,""))
B15: 1.8 | C15: Do your category strategies include a structured assessment of supply market dynamics — including supplier concentration risk, pricing trends, and alternative sourcing options? | E15: =IF(D15="Yes",1,IF(D15="No",0,""))
B16: 1.9 | C16: Do you apply differentiated sourcing and negotiation approaches by category, based on strategic importance and supply risk (e.g., Kraljic-style segmentation logic)? | E16: =IF(D16="Yes",1,IF(D16="No",0,""))
B17: 1.10 | C17: Are your category strategies explicitly designed to maximize local content spend and aligned with your organization's local content or LCGPA compliance objectives? | E17: =IF(D17="Yes",1,IF(D17="No",0,""))
B18: Subtotal | D18: =COUNTIF(D8:D17,"Yes")&" of 10" -> 0 of 10 | E18: =SUM(E8:E17) -> 0
B20: 2. SPEND ANALYSIS
B21: 2.1 | C21: Do you consolidate all purchasing data from ERP, invoices, purchase orders, and contracts into a single, centralized spend repository — rather than across disconnected systems and spreadsheets? | E21: =IF(D21="Yes",1,IF(D21="No",0,""))
B22: 2.2 | C22: Do you apply a standardized, minimum 3-level spend taxonomy consistently across all business units, departments, and procurement systems? | E22: =IF(D22="Yes",1,IF(D22="No",0,""))
B23: 2.3 | C23: Do you conduct formal spend reviews at least monthly, supported by a live or regularly refreshed dashboard? | E23: =IF(D23="Yes",1,IF(D23="No",0,""))
B24: 2.4 | C24: Is there a formally designated individual or role explicitly responsible for spend data quality, classification governance, and the delivery of spend insights? | E24: =IF(D24="Yes",1,IF(D24="No",0,""))
B25: 2.5 | C25: Does every spend review generate a documented, prioritized list of concrete sourcing actions or savings opportunities for follow-up? | E25: =IF(D25="Yes",1,IF(D25="No",0,""))
B26: 2.6 | C26: Is your local content (ICV-eligible) spend tracked, categorized, and automatically reported within your spend taxonomy — rather than managed manually or separately? | E26: =IF(D26="Yes",1,IF(D26="No",0,""))
B27: 2.7 | C27: Can you accurately identify your top 20 suppliers by total spend value within 24 hours, using your current procurement systems and data? | E27: =IF(D27="Yes",1,IF(D27="No",0,""))
B28: 2.8 | C28: Have you cleansed your supplier master data in the past 12 months to eliminate duplicates, inconsistent naming conventions, and misclassified records? | E28: =IF(D28="Yes",1,IF(D28="No",0,""))
B29: 2.9 | C29: Do you actively analyze off-contract and maverick spend as part of your regular spend review process to identify and remediate compliance leakage? | E29: =IF(D29="Yes",1,IF(D29="No",0,""))
B30: 2.10 | C30: Is spend data used proactively to inform sourcing decisions, annual budget planning, and supplier negotiations — rather than only for retrospective finance reporting or audit purposes? | E30: =IF(D30="Yes",1,IF(D30="No",0,""))
B31: Subtotal | D31: =COUNTIF(D21:D30,"Yes")&" of 10" -> 0 of 10 | E31: =SUM(E21:E30) -> 0
B33: 3. STRATEGIC SOURCING
B34: 3.1 | C34: Do you apply a structured, multi-step sourcing process — covering market analysis, demand planning, tendering, negotiation preparation, and contracting — for all categories above a defined spend threshold? | E34: =IF(D34="Yes",1,IF(D34="No",0,""))
B35: 3.2 | C35: Do you calculate and apply Total Cost of Ownership (TCO) analysis — not unit price alone — when evaluating supplier bids for strategic or high-value categories? | E35: =IF(D35="Yes",1,IF(D35="No",0,""))
B36: 3.3 | C36: Do you mandate a minimum of three competitive quotes or bids for all purchases above a formally defined spend threshold? | E36: =IF(D36="Yes",1,IF(D36="No",0,""))
B37: 3.4 | C37: Do you conduct formal supply market analysis — including price benchmarking, supplier landscape mapping, and competitive dynamics assessment — before launching a sourcing event? | E37: =IF(D37="Yes",1,IF(D37="No",0,""))
B38: 3.5 | C38: Do you develop a documented negotiation strategy — including defined targets, walk-away positions, and specific negotiation levers — before entering any major supplier negotiation? | E38: =IF(D38="Yes",1,IF(D38="No",0,""))
B39: 3.6 | C39: Do you use standardized RFX templates (RFI, RFQ, RFP) for sourcing events, aligned with internal stakeholders before distribution to the supplier market? | E39: =IF(D39="Yes",1,IF(D39="No",0,""))
B40: 3.7 | C40: Do you evaluate and shortlist suppliers based on pre-defined qualitative and quantitative criteria beyond price — such as quality, delivery reliability, financial stability, and local content contribution? | E40: =IF(D40="Yes",1,IF(D40="No",0,""))
B41: 3.8 | C41: Do you maintain and regularly update a vendor longlist or approved supplier database that is formally integrated into the sourcing process for each spend category? | E41: =IF(D41="Yes",1,IF(D41="No",0,""))
B42: 3.9 | C42: Do you formally evaluate supplier performance post-award and feed the results back into your sourcing strategy, supplier segmentation, and future sourcing decisions? | E42: =IF(D42="Yes",1,IF(D42="No",0,""))
B43: 3.10 | C43: Do you track and formally report realized sourcing savings against pre-defined targets on a category-by-category basis, with validation from finance or senior leadership? | E43: =IF(D43="Yes",1,IF(D43="No",0,""))
B44: Subtotal | D44: =COUNTIF(D34:D43,"Yes")&" of 10" -> 0 of 10 | E44: =SUM(E34:E43) -> 0
B46: 4. SUPPLIER RELATIONSHIP MANAGEMENT
...

Sheet 3. Results Dashboard
B3: Results Dashboard
B4: Procurement performance scoring across the four assessed dimensions
B6: OVERALL PROCUREMENT MATURITY
B7: ='2. Self-Assessment'!E59/40 -> 0 | D7: Maturity grade
D8: =IF('2. Self-Assessment'!E59/40<=0.4,"Foundational",IF('2. Self-Assessment'!E59/40<=0.65,"Developing",IF('2. Self-Assessment'!E59/40<=0.8,"Advanced","Best-in-Class"))) -> Foundational
D9: ="Total: "&'2. Self-Assessment'!E59&" of 40 practices in place" -> Total: 0 of 40 practices in place
B12: Score by dimension
B13: Dimension | C13: Yes answers | D13: Score % | E13: Score bar | F13: Maturity grade
B14: Category Management | C14: ='2. Self-Assessment'!E18&" of 10" -> 0 of 10 | D14: ='2. Self-Assessment'!E18/10 -> 0 | E14: ='2. Self-Assessment'!E18/10 -> 0 | F14: =IF('2. Self-Assessment'!E18/10<=0.4,"Foundational",IF('2. Self-Assessment'!E18/10<=0.65,"Developing",IF('2. Self-Assessment'!E18/10<=0.8,"Advanced","Best-in-Class"))) -> Foundational | H14: =D14+ROW(D14)/1000000 -> 1.4e-05
B15: Spend Analysis | C15: ='2. Self-Assessment'!E31&" of 10" -> 0 of 10 | D15: ='2. Self-Assessment'!E31/10 -> 0 | E15: ='2. Self-Assessment'!E31/10 -> 0 | F15: =IF('2. Self-Assessment'!E31/10<=0.4,"Foundational",IF('2. Self-Assessment'!E31/10<=0.65,"Developing",IF('2. Self-Assessment'!E31/10<=0.8,"Advanced","Best-in-Class"))) -> Foundational | H15: =D15+ROW(D15)/1000000 -> 1.5e-05
B16: Strategic Sourcing | C16: ='2. Self-Assessment'!E44&" of 10" -> 0 of 10 | D16: ='2. Self-Assessment'!E44/10 -> 0 | E16: ='2. Self-Assessment'!E44/10 -> 0 | F16: =IF('2. Self-Assessment'!E44/10<=0.4,"Foundational",IF('2. Self-Assessment'!E44/10<=0.65,"Developing",IF('2. Self-Assessment'!E44/10<=0.8,"Advanced","Best-in-Class"))) -> Foundational | H16: =D16+ROW(D16)/1000000 -> 1.6e-05
B17: Supplier Relationship Management | C17: ='2. Self-Assessment'!E57&" of 10" -> 0 of 10 | D17: ='2. Self-Assessment'!E57/10 -> 0 | E17: ='2. Self-Assessment'!E57/10 -> 0 | F17: =IF('2. Self-Assessment'!E57/10<=0.4,"Foundational",IF('2. Self-Assessment'!E57/10<=0.65,"Developing",IF('2. Self-Assessment'!E57/10<=0.8,"Advanced","Best-in-Class"))) -> Foundational | H17: =D17+ROW(D17)/1000000 -> 1.7e-05
B37: Interpretation of results
B38: =IF('2. Self-Assessment'!E59/40<=0.4,_xlfn._LONGTEXT("The procurement function sits at a foundational maturity level. Core capabilities are not yet consistently in place. Priority should be given to establishing standardized processes, a clean spend baseline, and category ownership before pursuing advanced v","alue levers."),IF('2. Self-Assessment'!E59/40<=0.65,_xlfn._LONGTEXT("The procurement function shows developing maturity. Capabilities are in place in parts of the organization but are applied inconsistently. Focus on standardizing processes across categories, scaling proven practices, and closing the most material capabili","ty gaps identified in the dimension scores."),IF('2. Self-Assessment'!E59/40<=0.8,_xlfn._LONGTEXT("The procurement function demonstrates good performance. Most strategic levers are in place and operating effectively. The next horizon is selective excellence: deepen supplier collaboration, sharpen analytics-driven decision-making, and embed procurement ","more strongly into business strategy."),"The procurement function is performing at a best-in-class level. The focus should now shift from building capability to sustaining excellence, scaling innovation with strategic suppliers, and using procurement as a competitive differentiator."))) -> The procurement function sits at a foundational maturity level. Core capabilities are not yet consistently in place. Priority should be given to establishing standardized processes, a clean spend baseline, and category ownership before pursuing advanced value levers.
B40: Suggested improvement priorities
B41: Priority 1 | C41: =INDEX(B14:B17,MATCH(SMALL(H14:H17,1),H14:H17,0)) -> Category Management | F41: =INDEX(D14:D17,MATCH(SMALL(H14:H17,1),H14:H17,0)) -> 0
B42: Priority 2 | C42: =INDEX(B14:B17,MATCH(SMALL(H14:H17,2),H14:H17,0)) -> Spend Analysis | F42: =INDEX(D14:D17,MATCH(SMALL(H14:H17,2),H14:H17,0)) -> 0
B43: Priority 3 | C43: =INDEX(B14:B17,MATCH(SMALL(H14:H17,3),H14:H17,0)) -> Strategic Sourcing | F43: =INDEX(D14:D17,MATCH(SMALL(H14:H17,3),H14:H17,0)) -> 0
B45: Refer to the '4. Recommendations' sheet for tailored improvement actions for each dimension and maturity level.

Sheet 4. Recommendations
B3: Improvement Recommendations
B4: Tailored actions by dimension and maturity level
B6: CATEGORY MANAGEMENT
B7: Your current level | C7: =IF('2. Self-Assessment'!E18/10<=0.4,"Foundational",IF('2. Self-Assessment'!E18/10<=0.65,"Developing",IF('2. Self-Assessment'!E18/10<=0.8,"Advanced","Best-in-Class")))&" | Score: "&TEXT('2. Self-Assessment'!E18/10,"0%") -> Foundational | Score: 0%
B8: Foundational | C8: • Establish a prioritized list of top spend categories and assign clear category ownership. • Develop a standard category strategy template covering market, suppliers, demand, and levers. • Run quick-win sourcing waves on the largest, simplest categories to build credibility. • Introduce a basic category classification (e.g. Kraljic matrix) to differentiate strategies.
B9: Developing | C9: • Roll out category strategies across all material categories with consistent quality standards. • Embed annual refresh cycles linked to budget planning and demand forecasting. • Strengthen stakeholder governance with formal category steering committees. • Build a category-level initiative pipeline tracking savings, risk, and ESG impact.
B10: Advanced | C10: • Differentiate strategies further by tiering categories on strategic value and complexity. • Integrate market intelligence subscriptions and structured supplier scouting per category. • Tie category KPIs to business outcomes (e.g. margin, time-to-market, resilience). • Drive cross-category synergies through coordinated demand and specification management.
B11: Best-in-Class | C11: • Use category strategies as enterprise value engines linked to corporate strategy. • Embed scenario planning and dynamic re-prioritization in response to market shifts. • Benchmark externally and share leading practices across business units and geographies. • Position category managers as trusted business advisors to senior leadership.
B13: SPEND ANALYSIS
B14: Your current level | C14: =IF('2. Self-Assessment'!E31/10<=0.4,"Foundational",IF('2. Self-Assessment'!E31/10<=0.65,"Developing",IF('2. Self-Assessment'!E31/10<=0.8,"Advanced","Best-in-Class")))&" | Score: "&TEXT('2. Self-Assessment'!E31/10,"0%") -> Foundational | Score: 0%
B15: Foundational | C15: • Consolidate spend data from all ERP and P2P systems into a single, clean baseline. • Implement a standardized spend taxonomy and classify the top 80% of spend. • Quantify off-contract and maverick spend and report it to procurement leadership. • Establish a quarterly spend review routine with key stakeholders.
B16: Developing | C16: • Move from one-off analyses to a continuously refreshed spend analytics dashboard. • Increase coverage of addressable spend under active procurement management. • Apply spend cube analysis (category × supplier × business unit × geography) systematically. • Link spend insights directly into the sourcing initiative pipeline and savings tracking.
B17: Advanced | C17: • Augment spend analytics with predictive insights (price forecasts, demand patterns, risk signals). • Integrate external benchmarks (e.g. should-cost, market price indices) into the analytics layer. • Automate classification using machine-learning enabled spend tools. • Use analytics to identify cross-category and cross-BU consolidation opportunities proactively.
B18: Best-in-Class | C18: • Deploy real-time spend intelligence accessible across the enterprise. • Use AI-driven anomaly detection on transactions to identify leakage and risk. • Integrate spend analytics with sustainability, risk, and resilience reporting. • Position spend analytics as a strategic decision-support capability for the business.
B20: STRATEGIC SOURCING
B21: Your current level | C21: =IF('2. Self-Assessment'!E44/10<=0.4,"Foundational",IF('2. Self-Assessment'!E44/10<=0.65,"Developing",IF('2. Self-Assessment'!E44/10<=0.8,"Advanced","Best-in-Class")))&" | Score: "&TEXT('2. Self-Assessment'!E44/10,"0%") -> Foundational | Score: 0%
B22: Foundational | C22: • Define a standard end-to-end strategic sourcing process and roll it out for major events. • Introduce structured RFx templates and basic e-sourcing tooling. • Move from price-only to a TCO-based evaluation approach on top categories. • Establish a savings tracking discipline linking negotiated savings to budgets.
B23: Developing | C23: • Embed pre-event market intelligence and supplier capability assessments as a standard step. • Scale e-sourcing tools across categories and harmonize RFx templates globally. • Develop negotiation playbooks differentiated by category type and supplier power. • Introduce contract management discipline covering performance, risk, and ESG clauses.
B24: Advanced | C24: • Integrate advanced techniques: should-cost modelling, scenario-based bidding, and bundling. • Build a sourcing center of excellence to support complex and high-value events. • Measure realized (not just negotiated) savings and feed results back to the business. • Use sourcing data to inform supplier consolidation and strategic supplier selection.
B25: Best-in-Class | C25: • Apply digital sourcing platforms with AI-supported bid analysis and award optimization. • Use sourcing as a lever for innovation, ESG, and resilience — not only cost. • Continuously optimize cycle time and effectiveness across the sourcing pipeline. • Position strategic sourcing as a recognized competitive advantage internally and externally.
B27: SUPPLIER RELATIONSHIP MANAGEMENT
B28: Your current level | C28: =IF('2. Self-Assessment'!E57/10<=0.4,"Foundational",IF('2. Self-Assessment'!E57/10<=0.65,"Developing",IF('2. Self-Assessment'!E57/10<=0.8,"Advanced","Best-in-Class")))&" | Score: "&TEXT('2. Self-Assessment'!E57/10,"0%") -> Foundational | Score: 0%
B29: Foundational | C29: • Segment suppliers based on spend, strategic importance, and risk to identify the critical few. • Define a basic SRM framework and assign relationship owners for top suppliers. • Introduce structured supplier performance reviews with key suppliers. • Implement basic supplier qualification and onboarding processes.
B30: Developing | C30: • Roll out differentiated engagement models (strategic, preferred, transactional) consistently. • Deploy balanced supplier scorecards covering quality, delivery, cost, service, and innovation. • Operationalize a supplier risk management process across financial, operational, and ESG risks. • Establish executive sponsorship and governance routines for top strategic suppliers.
B31: Advanced | C31: • Launch joint value-creation programs (innovation, cost-out, sustainability) with top suppliers. • Integrate ESG performance and compliance into supplier scorecards and governance. • Use SRM analytics to anticipate supplier risk and proactively manage performance issues. • Develop differentiated talent and capabilities for SRM (relationship managers, analysts).
B32: Best-in-Class | C32: • Co-invest with strategic suppliers in capability building, R&D, and shared infrastructure. • Use supplier ecosystems as a source of competitive differentiation and resilience. • Apply real-time supplier intelligence (financial, ESG, geopolitical) to dynamic decision-making. • Benchmark SRM externally and continuously raise the bar on supplier collaboration.
B35: Recommendations highlighted in yellow correspond to your current maturity level for that dimension.
